<!--
  KUAFU 桌面双轮腿机器人 — MuJoCo MJCF 仿真模型

  单一数值真源: kuafu_physics.py（项目顶层），几何 mm→m 换算。
  设计依据: docs/KUAFU.md（机构/硬件/整机参数）, docs/plans/...-design.md §三（仿真建模）。

  坐标系: 原点在髋面中心（两髋点 A-B 中点），+X 前向, +Y 左向, +Z 上向。
          驻留态轮恒接地，机身底 Z = D0 + r。

  机构: 对称并联五杆髋关节, 每腿 2-DOF。每腿两根串联肘链（髋A→曲柄 a→P1→连杆 b→Q，
        髋B→曲柄 a→P2→连杆 b→Q），Q 点用 <connect site1/site2> 物理铰接形成闭链。
        4 个 ST3215 舵机 (hip_A + hip_B 各左右) 全部独立位置控制, 对齐真机。
        左右腿完全独立, 各 2-DOF — KUAFU §6.1, §5.3。
        (对称步态 Q 在 X=0 只是 2-DOF 的一个特例, 非机构限制)

  用途: 同一 .xml 兼容 MJX（GPU 训练）与原生 MuJoCo（CPU 可视化/sim-to-real 对拍）。
        验证: python rl/verify/verify_model.py / launch_viewer.py

  数值出处标注: KUAFU §x 表示 docs/KUAFU.md 第 x 节; design §x 表示 design.md。
-->
<mujoco model="kuafu">

  <!-- ============================================================
       编译器 / 求解器选项
       design §3.1: timestep=0.002 (500Hz 物理子步, RL 50Hz 控制每步 10 子步);
                    Newton solver iterations=50 (闭链需多迭代防约束漂移)
       ============================================================ -->
  <compiler angle="radian" coordinate="local" autolimits="true"/>
  <option timestep="0.002" solver="Newton" iterations="50" cone="elliptic"/>

  <!-- ============================================================
       默认参数
       design §3.2: 闭链关节 armature/frictionloss 抑制数值振荡
       KUAFU §5.3.3: 被动铰链干摩擦 μ≈0.3 (初版) / 0.001 (升级轴承)
       ============================================================ -->
  <default>
    <joint armature="0.01" damping="0.05" frictionloss="0.005" limited="true"/>
    <geom condim="3" friction="0.8 0.02 0.001" rgba="0.6 0.6 0.7 1"/>
    <position kp="80" kv="2" forcerange="-2.94 2.94"/>   <!-- design §3.3: ST3215 位置环, forcerange=堵转±2.94Nm (连续安全1.0由reward惩罚) -->
    <motor ctrlrange="-1.1 1.1" forcerange="-1.1 1.1"/>        <!-- design §3.3: DDSM315 堵转 ±1.1 Nm -->
    <!-- 轮关节: armature=0 (物理轮毂惯量由 geom 质量自然计算, 不叠加额外电枢惯量) -->
    <default class="wheel">
      <joint armature="0" damping="0" frictionloss="0" limited="false"/>
    </default>
    <!-- 腿/机身连杆不参与碰撞, 只保留轮-地接触 (闭链关节 + equality 已约束运动学) -->
    <default class="leg">
      <geom contype="0" conaffinity="0"/>
    </default>
  </default>

  <!-- ============================================================
       视觉 / 地形
       ============================================================ -->
  <visual>
    <headlight diffuse="0.6 0.6 0.6" ambient="0.3 0.3 0.3" specular="0 0 0"/>
    <rgba haze="0.15 0.25 0.35 1"/>
    <global azimuth="120" elevation="-20"/>
  </visual>

  <asset>
    <texture type="skybox" builtin="gradient" rgb1="0.5 0.6 0.7" rgb2="0 0 0" width="256" height="256"/>
    <texture type="2d" name="groundplane" builtin="checker" mark="edge" rgb1="0.2 0.3 0.4" rgb2="0.1 0.2 0.3" width="512" height="512"/>
    <material name="groundplane" texture="groundplane" texuniform="true" texrepeat="5 5" reflectance="0.2"/>
    <!-- 粗糙地形 (DIFF_ROUGH): 高度场, 训练时由 KuafuMjxEnv._apply_rough 改写 hfield_data
         注入高度噪声; amplitude 随 difficulty 缩放 (0 → 全平, 退回平地)。
         MJX 3.10.0 支持 hfield×capsule 碰撞 (轮为 capsule)。64×64 网格 (~6.25cm/格)
         ≤ 轮半径 3.9cm, 保证凸起可被精确接触。 -->
    <hfield name="terrain" nrow="64" ncol="64" size="2.0 2.0 0.05 0.001"/>
  </asset>

  <worldbody>
    <light pos="0 0 1.5" dir="0 0 -1" diffuse="0.8 0.8 0.8"/>
    <geom name="floor" type="plane" size="0 0 0.05" material="groundplane" friction="0.8 0.02 0.001"/>
    <!-- 粗糙地形 hfield 覆盖 x∈[-1,3], y∈[-2,2]; 机器人出生在 x=0 处于 hfield 内 -->
    <geom name="terrain_hfield" type="hfield" hfield="terrain" pos="1.0 0 0" friction="0.8 0.02 0.001"/>
    <!-- 台阶 (M4 30mm): 4 级静态 box, 训练时由 KuafuMjxEnv._apply_terrain 按
          difficulty 缩放高度 (difficulty=0 → 高度≈0, 退回平地, 不破坏已验证物理) -->
    <geom name="step0" type="box" size="0.3 0.5 0.0005" pos="0.60 0 0.0005" friction="0.8 0.02 0.001" rgba="0.45 0.45 0.55 1"/>
    <geom name="step1" type="box" size="0.3 0.5 0.0005" pos="0.95 0 0.0005" friction="0.8 0.02 0.001" rgba="0.45 0.45 0.55 1"/>
    <geom name="step2" type="box" size="0.3 0.5 0.0005" pos="1.30 0 0.0005" friction="0.8 0.02 0.001" rgba="0.45 0.45 0.55 1"/>
    <geom name="step3" type="box" size="0.3 0.5 0.0005" pos="1.65 0 0.0005" friction="0.8 0.02 0.001" rgba="0.45 0.45 0.55 1"/>

    <!-- ============================================================
         机架 (floating base) — 机身盒体 + 电子件质量点
         KUAFU §4.1: 机身 240×196×50 mm; §5.4: COM 表回填压低到 71.1mm
         髋面 (A-B 中点) 为机身坐标系原点，Z=0 在髋面
         ============================================================ -->
    <body name="chassis" pos="0 0 0.097">  <!-- Z=0.097: 机身底=D0+r=58+39=97mm (KUAFU §4.1), 髋面=机身坐标系原点 -->
      <freejoint name="root"/>
      <inertial pos="0 0 0.003" mass="0.609" diaginertia="0.0014 0.0018 0.0022"/>
        <!-- 机架结构: 上甲板179g + 下甲板370g + 线材60g = 609g (9000he CAD实测体积×1.01), 电子件由下方质量点承担 -->
      <geom name="body_box" type="box" size="0.120 0.098 0.025" pos="0 0 0.025"
            rgba="0.5 0.5 0.6 1" mass="0" contype="0" conaffinity="0"/>  <!-- KUAFU §4.1: 240×196×50, 质量由 inertial 承担, 不参与碰撞 -->
      <!-- 电子件质量点 (KUAFU §5.4 COM 表, local Z = 设计世界Z - 髋面Z(97mm)) -->
      <body name="battery" pos="0 0 -0.049"><inertial pos="0 0 0" mass="0.285" diaginertia="1e-5 1e-5 1e-5"/></body>
      <body name="buck"    pos="0 0 -0.047"><inertial pos="0 0 0" mass="0.140" diaginertia="1e-5 1e-5 1e-5"/></body>
      <body name="pi5"     pos="0 0  0.025"><inertial pos="0 0 0" mass="0.085" diaginertia="1e-5 1e-5 1e-5"/></body>
      <body name="d435i"   pos="0.060 0 0.025"><inertial pos="0 0 0" mass="0.070" diaginertia="1e-5 1e-5 1e-5"/></body>
      <body name="stm32"   pos="0 0 0.008"><inertial pos="0 0 0" mass="0.095" diaginertia="1e-5 1e-5 1e-5"/></body>
      <body name="powerbus" pos="0 0 -0.044"><inertial pos="0 0 0" mass="0.022" diaginertia="1e-5 1e-5 1e-5"/></body>
      <body name="chargepak" pos="0 0 0.025"><inertial pos="0 0 0" mass="0.150" diaginertia="1e-5 1e-5 1e-5"/></body>
      <site name="imu" pos="0 0 0.025" size="0.005"/>   <!-- BMI088 位置 -->

      <!-- 舵机固定质量点 (ST3215 ×4, KUAFU §3.1: ~60g/台, 安装在侧壁 Y=±0.098) -->
      <body name="servo_LF" pos="-0.026 0.098 0"><inertial pos="0 0 0" mass="0.060" diaginertia="1e-5 1e-5 1e-5"/></body>
      <body name="servo_LB" pos=" 0.026 0.098 0"><inertial pos="0 0 0" mass="0.060" diaginertia="1e-5 1e-5 1e-5"/></body>
      <body name="servo_RF" pos="-0.026 -0.098 0"><inertial pos="0 0 0" mass="0.060" diaginertia="1e-5 1e-5 1e-5"/></body>
      <body name="servo_RB" pos=" 0.026 -0.098 0"><inertial pos="0 0 0" mass="0.060" diaginertia="1e-5 1e-5 1e-5"/></body>

      <!-- ============================================================
           左腿 (Y=+0.098) 闭链五杆 — 几何经 IK 精确解算
           驻留态 D0=58: P1=(-107,45.7) P2=(107,45.7) Q=(0,-58) mm
           q=0 即驻留姿态 (geom fromto 按驻留态绘制)
           ============================================================ -->
      <!-- A 链: 髋A → 曲柄 a → P1 → 连杆 b → Q -->
      <body name="crank_A_l" pos="-0.026 0.098 0">
        <joint name="hip_A_l" type="hinge" axis="0 1 0" range="-3.3 3.3"/>
        <geom name="crank_A_l_geom" type="capsule" class="leg" fromto="0 0 0  -0.081 0 0.0457" size="0.006" mass="0.036"/>
        <body name="link_A_l" pos="-0.081 0 0.0457">   <!-- P1 相对髋A -->
          <joint name="knee_A_l" type="hinge" axis="0 1 0" range="-3.14 3.14"/>
          <geom name="link_A_l_geom" type="capsule" class="leg" fromto="0 0 0  0.107 0 -0.1037" size="0.006" mass="0.035"/>
          <site name="Q_A_l" pos="0.107 0 -0.1037" size="0.003"/>   <!-- Q 相对 P1 -->
          <!-- 左轮: 挂在 Q 点 (link_A_l 末端), 随闭链运动; pos=Q 相对 P1 -->
          <body name="wheel_l" pos="0.107 0 -0.1037">
            <joint name="wheel_l" type="hinge" axis="0 1 0" class="wheel"/>
          <geom name="wheel_l_geom" type="capsule" size="0.03908 0.0087" zaxis="0 1 0" mass="0.349"
                  friction="0.8 0.02 0.001" rgba="0.1 0.1 0.1 1"/>
          </body>
        </body>
      </body>

      <!-- B 链: 髋B → 曲柄 a → P2 → 连杆 b → Q -->
      <body name="crank_B_l" pos="0.026 0.098 0">
        <joint name="hip_B_l" type="hinge" axis="0 1 0" range="-3.3 3.3"/>
        <geom name="crank_B_l_geom" type="capsule" class="leg" fromto="0 0 0  0.081 0 0.0457" size="0.006" mass="0.036"/>
        <body name="link_B_l" pos="0.081 0 0.0457">   <!-- P2 相对髋B -->
          <joint name="knee_B_l" type="hinge" axis="0 1 0" range="-3.14 3.14"/>
          <geom name="link_B_l_geom" type="capsule" class="leg" fromto="0 0 0  -0.107 0 -0.1037" size="0.006" mass="0.035"/>
          <site name="Q_B_l" pos="-0.107 0 -0.1037" size="0.003"/>  <!-- Q 相对 P2 -->
        </body>
      </body>

      <!-- ============================================================
           右腿 (Y=-0.098) 闭链五杆 — 几何与左腿一致 (仅 Y 镜像)
           ============================================================ -->
      <body name="crank_A_r" pos="-0.026 -0.098 0">
        <joint name="hip_A_r" type="hinge" axis="0 1 0" range="-3.3 3.3"/>
        <geom name="crank_A_r_geom" type="capsule" class="leg" fromto="0 0 0  -0.081 0 0.0457" size="0.006" mass="0.036"/>
        <body name="link_A_r" pos="-0.081 0 0.0457">
          <joint name="knee_A_r" type="hinge" axis="0 1 0" range="-3.14 3.14"/>
          <geom name="link_A_r_geom" type="capsule" class="leg" fromto="0 0 0  0.107 0 -0.1037" size="0.006" mass="0.035"/>
          <site name="Q_A_r" pos="0.107 0 -0.1037" size="0.003"/>
          <!-- 右轮: 挂在 Q 点 (link_A_r 末端), 随闭链运动; pos=Q 相对 P1 -->
          <body name="wheel_r" pos="0.107 0 -0.1037">
            <joint name="wheel_r" type="hinge" axis="0 1 0" class="wheel"/>
            <geom name="wheel_r_geom" type="capsule" size="0.03908 0.0087" zaxis="0 1 0" mass="0.349"
                  friction="0.8 0.02 0.001" rgba="0.1 0.1 0.1 1"/>
          </body>
        </body>
      </body>

      <body name="crank_B_r" pos="0.026 -0.098 0">
        <joint name="hip_B_r" type="hinge" axis="0 1 0" range="-3.3 3.3"/>
        <geom name="crank_B_r_geom" type="capsule" class="leg" fromto="0 0 0  0.081 0 0.0457" size="0.006" mass="0.036"/>
        <body name="link_B_r" pos="0.081 0 0.0457">
          <joint name="knee_B_r" type="hinge" axis="0 1 0" range="-3.14 3.14"/>
          <geom name="link_B_r_geom" type="capsule" class="leg" fromto="0 0 0  -0.107 0 -0.1037" size="0.006" mass="0.035"/>
          <site name="Q_B_r" pos="-0.107 0 -0.1037" size="0.003"/>
        </body>
      </body>

    </body>
  </worldbody>

  <!-- ============================================================
       排除自碰撞 (design §3.1)
       连杆间、连杆与机身间不计算碰撞，避免误触; 只保留轮-地接触
       ============================================================ -->
  <contact>
    <exclude body1="chassis" body2="crank_A_l"/>
    <exclude body1="chassis" body2="crank_B_l"/>
    <exclude body1="chassis" body2="crank_A_r"/>
    <exclude body1="chassis" body2="crank_B_r"/>
    <exclude body1="link_A_l" body2="link_B_l"/>
    <exclude body1="link_A_r" body2="link_B_r"/>
  </contact>

  <!-- ============================================================
       闭链约束 (design §3.2) — Q 点物理铰接 (2-DOF 五杆, 物理真实)
       每条腿是 2-DOF 并联五杆: 两个独立曲柄 (hip_A, hip_B) + 两连杆 (knee 被动) +
       Q 点闭链铰接。左右腿完全独立, 共 4 个 ST3215 舵机各自位置控制。
       用 <connect site1/site2> 锁 Q 点重合 = 真机两连杆在 Q 点的刚性铰接。
       硬 solver 参数保证闭链 gap < 0.1mm (实测 0.000mm, KUAFU §6.1 机构解算)。
       不用 joint equality: 那会把 2-DOF 锁成 1-DOF, 丢失 X 方向自由度。
       ============================================================ -->
  <equality>
    <connect name="loop_l" site1="Q_A_l" site2="Q_B_l"
             solref="0.005 0.5" solimp="0.999 0.9999 0.00001"/>
    <connect name="loop_r" site1="Q_A_r" site2="Q_B_r"
             solref="0.005 0.5" solimp="0.999 0.9999 0.00001"/>
  </equality>

  <!-- ============================================================
       执行器 (design §3.3)
       轮 = motor (力矩控制), 腿 = position (位置控制, 模拟 ST3215 PD)
       2-DOF 五杆: 4 个舵机 (hip_A + hip_B 各左右) 各自独立位置控制, 对齐真机
       ============================================================ -->
  <actuator>
    <!-- 轮: τ = ctrl × gear = ctrl (Nm), ctrlrange ±1.1 堵转 -->
    <motor name="tau_l" joint="wheel_l" gear="1"/>
    <motor name="tau_r" joint="wheel_r" gear="1"/>

    <!-- 腿: position actuator, ctrl=目标角(rad) 范围±2.0=joint range;
         kp/kv 直接写在 actuator 上 (default 中 motor 与 position 混合导致 kp 继承失效)。
         4 个舵机 (hip_A + hip_B 各左右) 全部独立驱动, 对齐真机 4×ST3215。 -->
    <position name="q_hip_A_l" joint="hip_A_l" kp="80" kv="2" forcerange="-2.94 2.94" ctrlrange="-3.3 3.3"/>
    <position name="q_hip_A_r" joint="hip_A_r" kp="80" kv="2" forcerange="-2.94 2.94" ctrlrange="-3.3 3.3"/>
    <position name="q_hip_B_l" joint="hip_B_l" kp="80" kv="2" forcerange="-2.94 2.94" ctrlrange="-3.3 3.3"/>
    <position name="q_hip_B_r" joint="hip_B_r" kp="80" kv="2" forcerange="-2.94 2.94" ctrlrange="-3.3 3.3"/>
  </actuator>

  <!-- ============================================================
       传感器 (design §3.1)
       IMU / 编码器 / 力矩回传 / base 特权 (teacher 用)
       ============================================================ -->
  <sensor>
    <accelerometer site="imu"/>
    <gyro site="imu"/>
    <framequat objtype="site" objname="imu"/>
    <framelinvel objtype="site" objname="imu"/>   <!-- 特权: teacher 用, student 不用 -->

    <jointpos joint="wheel_l"/><jointpos joint="wheel_r"/>
    <jointpos joint="hip_A_l"/><jointpos joint="hip_B_l"/>
    <jointpos joint="hip_A_r"/><jointpos joint="hip_B_r"/>
    <jointvel joint="wheel_l"/><jointvel joint="wheel_r"/>
    <jointvel joint="hip_A_l"/><jointvel joint="hip_B_l"/>
    <jointvel joint="hip_A_r"/><jointvel joint="hip_B_r"/>

    <actuatorfrc actuator="tau_l"/><actuatorfrc actuator="tau_r"/>
    <actuatorfrc actuator="q_hip_A_l"/><actuatorfrc actuator="q_hip_A_r"/>
    <actuatorfrc actuator="q_hip_B_l"/><actuatorfrc actuator="q_hip_B_r"/>
  </sensor>

  <!-- ============================================================
       驻留态 keyframe (D0=58)
       geom fromto 已按驻留姿态绘制, 故各关节 q≈0 即驻留态。
       root Z=0.097 (机身底=D0+r=97mm, KUAFU §4.1)。
       ============================================================ -->
  <keyframe>
    <key name="dwell" qpos="
      0 0 0.097 1 0 0 0
      0 0
      0 0 0 0
      0 0 0 0"/>
      <!-- root(7) + wheels(2) + hips(4: A_l,B_l,A_r,B_r 各独立 2-DOF) + knees(4) = 17 qpos -->
  </keyframe>

</mujoco>
